Workbook

Sheet Dashboard
A2: Mister & Miss BISU TROPIKO 2024
A3: HIMAMAT 2024
A4: September 6, 2023 | BISU Balilihan Multi-Purpose Covered Court
C26: TABULATOR

Sheet Semi-Final
B2: Mister & Miss BISU TROPIKO 2024
B3: HIMAMAT 2024
B4: September 6, 2024 | BISU Balilihan Multi-Purpose Covered Court
A7: CONSOLIDATED RESULTS
B9: Production Number
B11: Male Candidates | M11: Female Candidates
B13: Contestant No. | C13: Judge 1 | E13: Judge 2 | G13: Judge 3 | I13: TOTAL % | J13: TOTAL RANK | K13: FINAL RANK | M13: Contestant No. | N13: Judge 1 | P13: Judge 2 | R13: Judge 3 | T13: TOTAL % | U13: TOTAL RANK | V13: FINAL RANK
C14: % | D14: Rank | E14: % | F14: Rank | G14: % | H14: Rank | N14: % | O14: Rank | P14: % | Q14: Rank | R14: % | S14: Rank
B15: 1 | C15: =('[1]Production Number'!$G16/100)*100 -> 0.97 | D15: =_xlfn.RANK.AVG(C15,$C$15:$C$20) -> 1 | E15: =('[2]Production Number'!$G16/100)*100 -> 0.85 | F15: =_xlfn.RANK.AVG(E15,$E$15:$E$20) -> 3 | G15: =('[3]Production Number'!$G16/100)*100 -> 0.87 | H15: =_xlfn.RANK.AVG(G15,$G$15:$G$20) -> 4.5 | I15: =(C15+E15+G15)/3*100 -> 89.666667 | J15: =(D15+F15+H15) -> 8.5 | K15: =_xlfn.RANK.AVG(J15,$J$15:$J$20,1) -> 3 | M15: 1 | N15: =('[1]Production Number'!$O16/100)*100 -> 0.94 | O15: =_xlfn.RANK.AVG(N15,$N$15:$N$20) -> 3 | P15: =('[2]Production Number'!$O16/100)*100 -> 0.87 | Q15: =_xlfn.RANK.AVG(P15,P$15:P$20) -> 2 | R15: =('[3]Production Number'!$O16/100)*100 -> 0.86 | S15: =_xlfn.RANK.AVG(R15,R$15:R$20) -> 5 | T15: =(N15+P15+R15)/3*100 -> 89 | U15: =(O15+Q15+S15) -> 10 | V15: =_xlfn.RANK.AVG(U15,U$15:U$20,1) -> 3.5
B16: 2 | C16: =('[1]Production Number'!$G17/100)*100 -> 0.94 | D16: =_xlfn.RANK.AVG(C16,C$15:C$20) -> 5 | E16: =('[2]Production Number'!$G17/100)*100 -> 0.82 | F16: =_xlfn.RANK.AVG(E16,E$15:E$20) -> 6 | G16: =('[3]Production Number'!$G17/100)*100 -> 0.87 | H16: =_xlfn.RANK.AVG(G16,G$15:G$20) -> 4.5 | I16: =(C16+E16+G16)/3*100 -> 87.666667 | J16: =(D16+F16+H16) -> 15.5 | K16: =_xlfn.RANK.AVG(J16,J$15:J$20,1) -> 6 | M16: 2 | N16: =('[1]Production Number'!$O17/100)*100 -> 0.93 | O16: =_xlfn.RANK.AVG(N16,N$15:N$20) -> 5.5 | P16: =('[2]Production Number'!$O17/100)*100 -> 0.84 | Q16: =_xlfn.RANK.AVG(P16,P$15:P$20) -> 3.5 | R16: =('[3]Production Number'!$O17/100)*100 -> 0.92 | S16: =_xlfn.RANK.AVG(R16,R$15:R$20) -> 1 | T16: =(N16+P16+R16)/3*100 -> 89.666667 | U16: =(O16+Q16+S16) -> 10 | V16: =_xlfn.RANK.AVG(U16,U$15:U$20,1) -> 3.5
B17: 3 | C17: =('[1]Production Number'!$G18/100)*100 -> 0.95 | D17: =_xlfn.RANK.AVG(C17,C$15:C$20) -> 3 | E17: =('[2]Production Number'!$G18/100)*100 -> 0.85 | F17: =_xlfn.RANK.AVG(E17,E$15:E$20) -> 3 | G17: =('[3]Production Number'!$G18/100)*100 -> 0.94 | H17: =_xlfn.RANK.AVG(G17,G$15:G$20) -> 1 | I17: =(C17+E17+G17)/3*100 -> 91.333333 | J17: =(D17+F17+H17) -> 7 | K17: =_xlfn.RANK.AVG(J17,J$15:J$20,1) -> 1.5 | M17: 3 | N17: =('[1]Production Number'!$O18/100)*100 -> 0.93 | O17: =_xlfn.RANK.AVG(N17,N$15:N$20) -> 5.5 | P17: =('[2]Production Number'!$O18/100)*100 -> 0.83 | Q17: =_xlfn.RANK.AVG(P17,P$15:P$20) -> 5 | R17: =('[3]Production Number'!$O18/100)*100 -> 0.86 | S17: =_xlfn.RANK.AVG(R17,R$15:R$20) -> 5 | T17: =(N17+P17+R17)/3*100 -> 87.333333 | U17: =(O17+Q17+S17) -> 15.5 | V17: =_xlfn.RANK.AVG(U17,U$15:U$20,1) -> 6
B18: 4 | C18: =('[1]Production Number'!$G19/100)*100 -> 0.95 | D18: =_xlfn.RANK.AVG(C18,C$15:C$20) -> 3 | E18: =('[2]Production Number'!$G19/100)*100 -> 0.91 | F18: =_xlfn.RANK.AVG(E18,E$15:E$20) -> 1 | G18: =('[3]Production Number'!$G19/100)*100 -> 0.88 | H18: =_xlfn.RANK.AVG(G18,G$15:G$20) -> 3 | I18: =(C18+E18+G18)/3*100 -> 91.333333 | J18: =(D18+F18+H18) -> 7 | K18: 1 | M18: 4 | N18: =('[1]Production Number'!$O19/100)*100 -> 0.96 | O18: =_xlfn.RANK.AVG(N18,N$15:N$20) -> 1 | P18: =('[2]Production Number'!$O19/100)*100 -> 0.84 | Q18: =_xlfn.RANK.AVG(P18,P$15:P$20) -> 3.5 | R18: =('[3]Production Number'!$O19/100)*100 -> 0.86 | S18: =_xlfn.RANK.AVG(R18,R$15:R$20) -> 5 | T18: =(N18+P18+R18)/3*100 -> 88.666667 | U18: =(O18+Q18+S18) -> 9.5 | V18: =_xlfn.RANK.AVG(U18,U$15:U$20,1) -> 2
B19: 5 | C19: =('[1]Production Number'!$G20/100)*100 -> 0.92 | D19: =_xlfn.RANK.AVG(C19,C$15:C$20) -> 6 | E19: =('[2]Production Number'!$G20/100)*100 -> 0.85 | F19: =_xlfn.RANK.AVG(E19,E$15:E$20) -> 3 | G19: =('[3]Production Number'!$G20/100)*100 -> 0.9 | H19: =_xlfn.RANK.AVG(G19,G$15:G$20) -> 2 | I19: =(C19+E19+G19)/3*100 -> 89 | J19: =(D19+F19+H19) -> 11 | K19: =_xlfn.RANK.AVG(J19,J$15:J$20,1) -> 4 | M19: 5 | N19: =('[1]Production Number'!$O20/100)*100 -> 0.94 | O19: =_xlfn.RANK.AVG(N19,N$15:N$20) -> 3 | P19: =('[2]Production Number'!$O20/100)*100 -> 0.88 | Q19: =_xlfn.RANK.AVG(P19,P$15:P$20) -> 1 | R19: =('[3]Production Number'!$O20/100)*100 -> 0.91 | S19: =_xlfn.RANK.AVG(R19,R$15:R$20) -> 2 | T19: =(N19+P19+R19)/3*100 -> 91 | U19: =(O19+Q19+S19) -> 6 | V19: =_xlfn.RANK.AVG(U19,U$15:U$20,1) -> 1
B20: 6 | C20: =('[1]Production Number'!$G21/100)*100 -> 0.95 | D20: =_xlfn.RANK.AVG(C20,C$15:C$20) -> 3 | E20: =('[2]Production Number'!$G21/100)*100 -> 0.84 | F20: =_xlfn.RANK.AVG(E20,E$15:E$20) -> 5 | G20: =('[3]Production Number'!$G21/100)*100 -> 0.79 | H20: =_xlfn.RANK.AVG(G20,G$15:G$20) -> 6 | I20: =(C20+E20+G20)/3*100 -> 86 | J20: =(D20+F20+H20) -> 14 | K20: =_xlfn.RANK.AVG(J20,J$15:J$20,1) -> 5 | M20: 6 | N20: =('[1]Production Number'!$O21/100)*100 -> 0.94 | O20: =_xlfn.RANK.AVG(N20,N$15:N$20) -> 3 | P20: =('[2]Production Number'!$O21/100)*100 -> 0.82 | Q20: =_xlfn.RANK.AVG(P20,P$15:P$20) -> 6 | R20: =('[3]Production Number'!$O21/100)*100 -> 0.9 | S20: =_xlfn.RANK.AVG(R20,R$15:R$20) -> 3 | T20: =(N20+P20+R20)/3*100 -> 88.666667 | U20: =(O20+Q20+S20) -> 12 | V20: =_xlfn.RANK.AVG(U20,U$15:U$20,1) -> 5
B22: Tropical Attire
B24: Male Candidates | M24: Female Candidates
B26: Contestant No. | C26: Judge 1 | E26: Judge 2 | G26: Judge 3 | I26: TOTAL % | J26: TOTAL RANK | K26: FINAL RANK | M26: Contestant No. | N26: Judge 1 | P26: Judge 2 | R26: Judge 3 | T26: TOTAL % | U26: TOTAL RANK | V26: FINAL RANK
C27: % | D27: Rank | E27: % | F27: Rank | G27: % | H27: Rank | N27: % | O27: Rank | P27: % | Q27: Rank | R27: % | S27: Rank
B28: 1 | C28: =(#REF!/100)*100 -> #REF! | D28: =_xlfn.RANK.AVG(C28,$C$28:$C$33) -> #REF! | E28: =('[2]Tropical Attire'!$G16/100)*100 -> 0.85 | F28: =_xlfn.RANK.AVG(E28,E$28:E$33) -> 5 | G28: =('[3]Tropical Attire'!$G16/100)*100 -> 0.91 | H28: =_xlfn.RANK.AVG(G28,G$28:G$33) -> 4 | I28: =(C28+E28+G28)/3*100 -> #REF! | J28: =(D28+F28+H28) -> #REF! | K28: =_xlfn.RANK.AVG(J28,J$28:J$33,1) -> #REF! | M28: 1 | N28: =(#REF!/100)*100 -> #REF! | O28: =_xlfn.RANK.AVG(N28,$N28:$N33) -> #REF! | P28: =('[2]Tropical Attire'!$O16/100)*100 -> 0.89 | Q28: =_xlfn.RANK.AVG(P28,P$28:P$33) -> 2 | R28: =('[3]Tropical Attire'!$O16/100)*100 -> 0.89 | S28: =_xlfn.RANK.AVG(R28,R$28:R$33) -> 3.5 | T28: =(N28+P28+R28)/3*100 -> #REF! | U28: =(O28+Q28+S28) -> #REF! | V28: =_xlfn.RANK.AVG(U28,U$28:U$33,1) -> #REF!
B29: 2 | C29: =(#REF!/100)*100 -> #REF! | D29: =_xlfn.RANK.AVG(C29,C$28:C$33) -> #REF! | E29: =('[2]Tropical Attire'!$G17/100)*100 -> 0.93 | F29: =_xlfn.RANK.AVG(E29,E$28:E$33) -> 1 | G29: =('[3]Tropical Attire'!$G17/100)*100 -> 0.87 | H29: =_xlfn.RANK.AVG(G29,G$28:G$33) -> 6 | I29: =(C29+E29+G29)/3*100 -> #REF! | J29: =(D29+F29+H29) -> #REF! | K29: =_xlfn.RANK.AVG(J29,J$28:J$33,1) -> #REF! | M29: 2 | N29: =(#REF!/100)*100 -> #REF! | O29: =_xlfn.RANK.AVG(N29,N$28:N$33) -> #REF! | P29: =('[2]Tropical Attire'!$O17/100)*100 -> 0.92 | Q29: =_xlfn.RANK.AVG(P29,P$28:P$33) -> 1 | R29: =('[3]Tropical Attire'!$O17/100)*100 -> 0.92 | S29: =_xlfn.RANK.AVG(R29,R$28:R$33) -> 1 | T29: =(N29+P29+R29)/3*100 -> #REF! | U29: =(O29+Q29+S29) -> #REF! | V29: =_xlfn.RANK.AVG(U29,U$28:U$33,1) -> #REF!
B30: 3 | C30: =(#REF!/100)*100 -> #REF! | D30: =_xlfn.RANK.AVG(C30,$C$28:$C$33) -> #REF! | E30: =('[2]Tropical Attire'!$G18/100)*100 -> 0.84 | F30: =_xlfn.RANK.AVG(E30,E$28:E$33) -> 6 | G30: =('[3]Tropical Attire'!$G18/100)*100 -> 0.93 | H30: =_xlfn.RANK.AVG(G30,G$28:G$33) -> 2 | I30: =(C30+E30+G30)/3*100 -> #REF! | J30: =(D30+F30+H30) -> #REF! | K30: =_xlfn.RANK.AVG(J30,J$28:J$33,1) -> #REF! | M30: 3 | N30: =(#REF!/100)*100 -> #REF! | O30: =_xlfn.RANK.AVG(N30,N$28:N$33) -> #REF! | P30: =('[2]Tropical Attire'!$O18/100)*100 -> 0.85 | Q30: =_xlfn.RANK.AVG(P30,P$28:P$33) -> 6 | R30: =('[3]Tropical Attire'!$O18/100)*100 -> 0.87 | S30: =_xlfn.RANK.AVG(R30,R$28:R$33) -> 6 | T30: =(N30+P30+R30)/3*100 -> #REF! | U30: =(O30+Q30+S30) -> #REF! | V30: =_xlfn.RANK.AVG(U30,U$28:U$33,1) -> #REF!
B31: 4 | C31: =(#REF!/100)*100 -> #REF! | D31: =_xlfn.RANK.AVG(C31,$C$28:$C$33) -> #REF! | E31: =('[2]Tropical Attire'!$G19/100)*100 -> 0.86 | F31: =_xlfn.RANK.AVG(E31,E$28:E$33) -> 4 | G31: =('[3]Tropical Attire'!$G19/100)*100 -> 0.89 | H31: =_xlfn.RANK.AVG(G31,G$28:G$33) -> 5 | I31: =(C31+E31+G31)/3*100 -> #REF! | J31: =(D31+F31+H31) -> #REF! | K31: =_xlfn.RANK.AVG(J31,J$28:J$33,1) -> #REF! | M31: 4 | N31: =(#REF!/100)*100 -> #REF! | O31: =_xlfn.RANK.AVG(N31,N$28:N$33) -> #REF! | P31: =('[2]Tropical Attire'!$O19/100)*100 -> 0.88 | Q31: =_xlfn.RANK.AVG(P31,P$28:P$33) -> 4 | R31: =('[3]Tropical Attire'!$O19/100)*100 -> 0.89 | S31: =_xlfn.RANK.AVG(R31,R$28:R$33) -> 3.5 | T31: =(N31+P31+R31)/3*100 -> #REF! | U31: =(O31+Q31+S31) -> #REF! | V31: =_xlfn.RANK.AVG(U31,U$28:U$33,1) -> #REF!
B32: 5 | C32: =(#REF!/100)*100 -> #REF! | D32: =_xlfn.RANK.AVG(C32,$C$28:$C$33) -> #REF! | E32: =('[2]Tropical Attire'!$G20/100)*100 -> 0.87 | F32: =_xlfn.RANK.AVG(E32,E$28:E$33) -> 3 | G32: =('[3]Tropical Attire'!$G20/100)*100 -> 0.94 | H32: =_xlfn.RANK.AVG(G32,G$28:G$33) -> 1 | I32: =(C32+E32+G32)/3*100 -> #REF! | J32: =(D32+F32+H32) -> #REF! | K32: =_xlfn.RANK.AVG(J32,J$28:J$33,1) -> #REF! | M32: 5 | N32: =(#REF!/100)*100 -> #REF! | O32: =_xlfn.RANK.AVG(N32,N$28:N$33) -> #REF! | P32: =('[2]Tropical Attire'!$O20/100)*100 -> 0.88 | Q32: =_xlfn.RANK.AVG(P32,P$28:P$33) -> 4 | R32: =('[3]Tropical Attire'!$O20/100)*100 -> 0.9 | S32: =_xlfn.RANK.AVG(R32,R$28:R$33) -> 2 | T32: =(N32+P32+R32)/3*100 -> #REF! | U32: =(O32+Q32+S32) -> #REF! | V32: =_xlfn.RANK.AVG(U32,U$28:U$33,1) -> #REF!
B33: 6 | C33: =(#REF!/100)*100 -> #REF! | D33: =_xlfn.RANK.AVG(C33,$C$28:$C$33) -> #REF! | E33: =('[2]Tropical Attire'!$G21/100)*100 -> 0.9 | F33: =_xlfn.RANK.AVG(E33,E$28:E$33) -> 2 | G33: =('[3]Tropical Attire'!$G21/100)*100 -> 0.92 | H33: =_xlfn.RANK.AVG(G33,G$28:G$33) -> 3 | I33: =(C33+E33+G33)/3*100 -> #REF! | J33: =(D33+F33+H33) -> #REF! | K33: =_xlfn.RANK.AVG(J33,J$28:J$33,1) -> #REF! | M33: 6 | N33: =(#REF!/100)*100 -> #REF! | O33: =_xlfn.RANK.AVG(N33,N$28:N$33) -> #REF! | P33: =('[2]Tropical Attire'!$O21/100)*100 -> 0.88 | Q33: =_xlfn.RANK.AVG(P33,P$28:P$33) -> 4 | R33: =('[3]Tropical Attire'!$O21/100)*100 -> 0.88 | S33: =_xlfn.RANK.AVG(R33,R$28:R$33) -> 5 | T33: =(N33+P33+R33)/3*100 -> #REF! | U33: =(O33+Q33+S33) -> #REF! | V33: =_xlfn.RANK.AVG(U33,U$28:U$33,1) -> #REF!
B35: Casual Interview
B37: Male Candidates | M37: Female Candidates
B39: Contestant No. | C39: Judge 1 | E39: Judge 2 | G39: Judge 3 | I39: TOTAL % | J39: TOTAL RANK | K39: FINAL RANK | M39: Contestant No. | N39: Judge 1 | P39: Judge 2 | R39: Judge 3 | T39: TOTAL % | U39: TOTAL RANK | V39: FINAL RANK
C40: % | D40: Rank | E40: % | F40: Rank | G40: % | H40: Rank | N40: % | O40: Rank | P40: % | Q40: Rank | R40: % | S40: Rank
B41: 1 | C41: =('[1]Casual Interview'!$G16/100)*100 -> 0.86 | D41: =_xlfn.RANK.AVG(C41,$C$41:$C$46) -> 6 | E41: =('[2]Casual Interview'!$G16/100)*100 -> 0.8 | F41: =_xlfn.RANK.AVG(E41,$E$41:$E$46) -> 6 | G41: =('[3]Casual Interview'!$G16/100)*100 -> 0.85 | H41: =_xlfn.RANK.AVG(G41,G$41:G$46) -> 5 | I41: =(C41+E41+G41)/3*100 -> 83.666667 | J41: =(D41+F41+H41) -> 17 | K41: =_xlfn.RANK.AVG(J41,J$41:J$46,1) -> 6 | M41: 1 | N41: =('[1]Casual Interview'!$O16/100)*100 -> 0.85 | O41: =_xlfn.RANK.AVG(N41,$N$41:$N$46) -> 4.5 | P41: =('[2]Casual Interview'!$O16/100)*100 -> 0.86 | Q41: =_xlfn.RANK.AVG(P41,P$41:P$46) -> 3 | R41: =('[3]Casual Interview'!$O16/100)*100 -> 0.86 | S41: =_xlfn.RANK.AVG(R41,R$41:R$46) -> 5 | T41: =(N41+P41+R41)/3*100 -> 85.666667 | U41: =(O41+Q41+S41) -> 12.5 | V41: =_xlfn.RANK.AVG(U41,U$41:U$46,1) -> 4
B42: 2 | C42: =('[1]Casual Interview'!$G17/100)*100 -> 0.93 | D42: =_xlfn.RANK.AVG(C42,$C$41:$C$46) -> 3.5 | E42: =('[2]Casual Interview'!$G17/100)*100 -> 0.87 | F42: =_xlfn.RANK.AVG(E42,$E$41:$E$46) -> 3.5 | G42: =('[3]Casual Interview'!$G17/100)*100 -> 0.86 | H42: =_xlfn.RANK.AVG(G42,G$41:G$46) -> 4 | I42: =(C42+E42+G42)/3*100 -> 88.666667 | J42: =(D42+F42+H42) -> 11 | K42: =_xlfn.RANK.AVG(J42,J$41:J$46,1) -> 4 | M42: 2 | N42: =('[1]Casual Interview'!$O17/100)*100 -> 0.92 | O42: =_xlfn.RANK.AVG(N42,$N$41:$N$46) -> 2 | P42: =('[2]Casual Interview'!$O17/100)*100 -> 0.87 | Q42: =_xlfn.RANK.AVG(P42,P$41:P$46) -> 2 | R42: =('[3]Casual Interview'!$O17/100)*100 -> 0.94 | S42: =_xlfn.RANK.AVG(R42,R$41:R$46) -> 1 | T42: =(N42+P42+R42)/3*100 -> 91 | U42: =(O42+Q42+S42) -> 5 | V42: =_xlfn.RANK.AVG(U42,U$41:U$46,1) -> 1
B43: 3 | C43: =('[1]Casual Interview'!$G18/100)*100 -> 0.95 | D43: =_xlfn.RANK.AVG(C43,$C$41:$C$46) -> 2 | E43: =('[2]Casual Interview'!$G18/100)*100 -> 0.87 | F43: =_xlfn.RANK.AVG(E43,$E$41:$E$46) -> 3.5 | G43: =('[3]Casual Interview'!$G18/100)*100 -> 0.95 | H43: =_xlfn.RANK.AVG(G43,G$41:G$46) -> 1 | I43: =(C43+E43+G43)/3*100 -> 92.333333 | J43: =(D43+F43+H43) -> 6.5 | K43: =_xlfn.RANK.AVG(J43,J$41:J$46,1) -> 2 | M43: 3 | N43: =('[1]Casual Interview'!$O18/100)*100 -> 0.85 | O43: =_xlfn.RANK.AVG(N43,$N$41:$N$46) -> 4.5 | P43: =('[2]Casual Interview'!$O18/100)*100 -> 0.82 | Q43: =_xlfn.RANK.AVG(P43,P$41:P$46) -> 5 | R43: =('[3]Casual Interview'!$O18/100)*100 -> 0.88 | S43: =_xlfn.RANK.AVG(R43,R$41:R$46) -> 4 | T43: =(N43+P43+R43)/3*100 -> 85 | U43: =(O43+Q43+S43) -> 13.5 | V43: =_xlfn.RANK.AVG(U43,U$41:U$46,1) -> 5
B44: 4 | C44: =('[1]Casual Interview'!$G19/100)*100 -> 0.92 | D44: =_xlfn.RANK.AVG(C44,$C$41:$C$46) -> 5 | E44: =('[2]Casual Interview'!$G19/100)*100 -> 0.83 | F44: =_xlfn.RANK.AVG(E44,$E$41:$E$46) -> 5 | G44: =('[3]Casual Interview'!$G19/100)*100 -> 0.84 | H44: =_xlfn.RANK.AVG(G44,G$41:G$46) -> 6 | I44: =(C44+E44+G44)/3*100 -> 86.333333 | J44: =(D44+F44+H44) -> 16 | K44: =_xlfn.RANK.AVG(J44,J$41:J$46,1) -> 5 | M44: 4 | N44: =('[1]Casual Interview'!$O19/100)*100 -> 0.94 | O44: =_xlfn.RANK.AVG(N44,$N$41:$N$46) -> 1 | P44: =('[2]Casual Interview'!$O19/100)*100 -> 0.85 | Q44: =_xlfn.RANK.AVG(P44,P$41:P$46) -> 4 | R44: =('[3]Casual Interview'!$O19/100)*100 -> 0.92 | S44: =_xlfn.RANK.AVG(R44,R$41:R$46) -> 2 | T44: =(N44+P44+R44)/3*100 -> 90.333333 | U44: =(O44+Q44+S44) -> 7 | V44: =_xlfn.RANK.AVG(U44,U$41:U$46,1) -> 2.5
B45: 5 | C45: =('[1]Casual Interview'!$G20/100)*100 -> 0.93 | D45: =_xlfn.RANK.AVG(C45,$C$41:$C$46) -> 3.5 | E45: =('[2]Casual Interview'!$G20/100)*100 -> 0.9 | F45: =_xlfn.RANK.AVG(E45,$E$41:$E$46) -> 1 | G45: =('[3]Casual Interview'!$G20/100)*100 -> 0.87 | H45: =_xlfn.RANK.AVG(G45,G$41:G$46) -> 3 | I45: =(C45+E45+G45)/3*100 -> 90 | J45: =(D45+F45+H45) -> 7.5 | K45: =_xlfn.RANK.AVG(J45,J$41:J$46,1) -> 3 | M45: 5 | N45: =('[1]Casual Interview'!$O20/100)*100 -> 0.88 | O45: =_xlfn.RANK.AVG(N45,$N$41:$N$46) -> 3 | P45: =('[2]Casual Interview'!$O20/100)*100 -> 0.88 | Q45: =_xlfn.RANK.AVG(P45,P$41:P$46) -> 1 | R45: =('[3]Casual Interview'!$O20/100)*100 -> 0.9 | S45: =_xlfn.RANK.AVG(R45,R$41:R$46) -> 3 | T45: =(N45+P45+R45)/3*100 -> 88.666667 | U45: =(O45+Q45+S45) -> 7 | V45: =_xlfn.RANK.AVG(U45,U$41:U$46,1) -> 2.5
B46: 6 | C46: =('[1]Casual Interview'!$G21/100)*100 -> 0.98 | D46: =_xlfn.RANK.AVG(C46,$C$41:$C$46) -> 1 | E46: =('[2]Casual Interview'!$G21/100)*100 -> 0.89 | F46: =_xlfn.RANK.AVG(E46,$E$41:$E$46) -> 2 | G46: =('[3]Casual Interview'!$G21/100)*100 -> 0.94 | H46: =_xlfn.RANK.AVG(G46,G$41:G$46) -> 2 | I46: =(C46+E46+G46)/3*100 -> 93.666667 | J46: =(D46+F46+H46) -> 5 | K46: =_xlfn.RANK.AVG(J46,J$41:J$46,1) -> 1 | M46: 6 | N46: =('[1]Casual Interview'!$O21/100)*100 -> 0.84 | O46: =_xlfn.RANK.AVG(N46,$N$41:$N$46) -> 6 | P46: =('[2]Casual Interview'!$O21/100)*100 -> 0.79 | Q46: =_xlfn.RANK.AVG(P46,P$41:P$46) -> 6 | R46: =('[3]Casual Interview'!$O21/100)*100 -> 0.8 | S46: =_xlfn.RANK.AVG(R46,R$41:R$46) -> 6 | T46: =(N46+P46+R46)/3*100 -> 81 | U46: =(O46+Q46+S46) -> 18 | V46: =_xlfn.RANK.AVG(U46,U$41:U$46,1) -> 6
B48: Top 3 Finalists
B49: (Point System)
B51: Male Candidates | M51: Female Candidates
B53: Contestant No. | C53: Category | I53: TOTAL % | J53: TOTAL RANK | K53: FINAL RANK | M53: Contestant No. | N53: Category | T53: TOTAL % | U53: TOTAL RANK | V53: FINAL RANK
C54: Production Number | F54: Vintage Attire Presentation | N54: Production Number | Q54: Vintage Attire Presentation
C55: Points Earned | D55: 0.5 | E55: Rank | F55: Points Earned | G55: 0.5 | H55: Rank | N55: Points Earned | O55: 0.5 | P55: Rank | Q55: Points Earned | R55: 0.5 | S55: Rank
...

Sheet Final
B2: Mister & Miss BISU TROPIKO 2024
B3: HIMAMAT 2024
B4: September 6, 2024 | BISU Balilihan Multi-Purpose Covered Court
A7: CONSOLIDATED RESULT
B11: Question and Answer
B12: Final Round
B14: Male Candidates | M14: Female Candidates
B16: Contestant No. | C16: Judge 1 | E16: Judge 2 | G16: Judge 3 | I16: TOTAL % | J16: TOTAL RANK | K16: FINAL RANK | M16: Contestant No. | N16: Judge 1 | P16: Judge 2 | R16: Judge 3 | T16: TOTAL % | U16: TOTAL RANK | V16: FINAL RANK
C17: % | D17: Rank | E17: % | F17: Rank | G17: % | H17: Rank | N17: % | O17: Rank | P17: % | Q17: Rank | R17: % | S17: Rank
B18: =INDEX('Semi-Final'!B$71:B$76,MATCH(SMALL('Semi-Final'!K$71:K$76,1),'Semi-Final'!K$71:K$76,0)) -> #REF! | C18: =#REF! -> #REF! | D18: =_xlfn.RANK.AVG(C18,C$18:C$20) -> #REF! | E18: ='[2]Top 3'!$F$16 -> 0.88 | F18: =_xlfn.RANK.AVG(E18,E$18:E$20) -> 1 | G18: ='[3]Top 3'!$F$16 -> 0.87 | H18: =_xlfn.RANK.AVG(G18,G$18:G$20) -> 3 | I18: =(C18+E18+G18)/3*100 -> #REF! | J18: =(D18+F18+H18) -> #REF! | K18: =_xlfn.RANK.AVG(J18,$J$18:$J$20,1) -> #REF! | M18: =INDEX('Semi-Final'!M$71:M$76,MATCH(SMALL('Semi-Final'!V$71:V$76,1),'Semi-Final'!V$71:V$76,0)) -> #REF! | N18: =#REF! -> #REF! | O18: =_xlfn.RANK.AVG(N18,N$18:N$20) -> #REF! | P18: ='[2]Top 3'!$M$16 -> 0.91 | Q18: =_xlfn.RANK.AVG(P18,P$18:P$20) -> 2 | R18: ='[3]Top 3'!$M$16 -> 0.95 | S18: =_xlfn.RANK.AVG(R18,R$18:R$20) -> 1 | T18: =(N18+P18+R18)/3*100 -> #REF! | U18: =(O18+Q18+S18) -> #REF! | V18: =_xlfn.RANK.AVG(U18,$U$18:$U$20,1) -> #REF!
B19: =INDEX('Semi-Final'!B$71:B$76,MATCH(SMALL('Semi-Final'!K$71:K$76,2),'Semi-Final'!K$71:K$76,0)) -> #REF! | C19: =#REF! -> #REF! | D19: =_xlfn.RANK.AVG(C19,C$18:C$20) -> #REF! | E19: ='[2]Top 3'!$F$17 -> 0.83 | F19: =_xlfn.RANK.AVG(E19,E$18:E$20) -> 3 | G19: ='[3]Top 3'!$F$17 -> 0.91 | H19: =_xlfn.RANK.AVG(G19,G$18:G$20) -> 1 | I19: =(C19+E19+G19)/3*100 -> #REF! | J19: =(D19+F19+H19) -> #REF! | K19: =_xlfn.RANK.AVG(J19,$J$18:$J$20,1) -> #REF! | M19: =INDEX('Semi-Final'!M$71:M$76,MATCH(SMALL('Semi-Final'!V$71:V$76,2),'Semi-Final'!V$71:V$76,0)) -> #REF! | N19: =#REF! -> #REF! | O19: =_xlfn.RANK.AVG(N19,N$18:N$20) -> #REF! | P19: ='[2]Top 3'!$M$17 -> 0.92 | Q19: =_xlfn.RANK.AVG(P19,P$18:P$20) -> 1 | R19: ='[3]Top 3'!$M$17 -> 0.94 | S19: =_xlfn.RANK.AVG(R19,R$18:R$20) -> 2 | T19: =(N19+P19+R19)/3*100 -> #REF! | U19: =(O19+Q19+S19) -> #REF! | V19: =_xlfn.RANK.AVG(U19,$U$18:$U$20,1) -> #REF!
B20: =INDEX('Semi-Final'!B$71:B$76,MATCH(SMALL('Semi-Final'!K$71:K$76,3),'Semi-Final'!K$71:K$76,0)) -> #REF! | C20: =#REF! -> #REF! | D20: =_xlfn.RANK.AVG(C20,C$18:C$20) -> #REF! | E20: ='[2]Top 3'!$F$18 -> 0.86 | F20: =_xlfn.RANK.AVG(E20,E$18:E$20) -> 2 | G20: ='[3]Top 3'!$F$18 -> 0.9 | H20: =_xlfn.RANK.AVG(G20,G$18:G$20) -> 2 | I20: =(C20+E20+G20)/3*100 -> #REF! | J20: =(D20+F20+H20) -> #REF! | K20: =_xlfn.RANK.AVG(J20,$J$18:$J$20,1) -> #REF! | M20: =INDEX('Semi-Final'!M$71:M$76,MATCH(SMALL('Semi-Final'!V$71:V$76,3),'Semi-Final'!V$71:V$76,0)) -> #REF! | N20: =#REF! -> #REF! | O20: =_xlfn.RANK.AVG(N20,N$18:N$20) -> #REF! | P20: ='[2]Top 3'!$M$18 -> 0.86 | Q20: =_xlfn.RANK.AVG(P20,P$18:P$20) -> 3 | R20: ='[3]Top 3'!$M$18 -> 0.93 | S20: =_xlfn.RANK.AVG(R20,R$18:R$20) -> 3 | T20: =(N20+P20+R20)/3*100 -> #REF! | U20: =(O20+Q20+S20) -> #REF! | V20: =_xlfn.RANK.AVG(U20,$U$18:$U$20,1) -> #REF!
B23: Final Round
B24: (Rank System)
B26: Male Candidates | M26: Female Candidates
B28: Contestant No. | C28: Category | I28: TOTAL RANK | J28: TOTAL % | K28: FINAL RANK | M28: Contestant No. | N28: Category | T28: TOTAL RANK | U28: TOTAL % | V28: FINAL RANK
C29: Production Number & Vintage Attire Presentation | F29: Question and Answer | N29: Production Number | Q29: Vintage Attire Presentation
C30: Rank | D30: 0.7 | F30: Rank | G30: 0.3 | N30: Rank | O30: 0.5 | Q30: Rank | R30: 0.5
B31: 1 | C31: =#REF! -> #REF! | D31: =(C31/100)*50 -> #REF! | F31: =#REF! -> #REF! | G31: =($F31*0.3) -> #REF! | I31: =(C31+F31) -> #REF! | J31: =(D31+G31)/2 -> #REF! | K31: =_xlfn.RANK.AVG(J31,#REF!,1) -> #REF! | M31: 1 | N31: =#REF! -> #REF! | O31: =(N31/100)*50 -> #REF! | Q31: =#REF! -> #REF! | R31: =($F31*0.5) -> #REF! | T31: =(N31+Q31) -> #REF! | U31: =(O31+R31)/2 -> #REF! | V31: =_xlfn.RANK.AVG(U31,#REF!,1) -> #REF!
B32: 3 | C32: =#REF! -> #REF! | D32: =(C32/100)*50 -> #REF! | F32: =#REF! -> #REF! | G32: =($F32*0.5) -> #REF! | I32: =(C32+F32) -> #REF! | J32: =(D32+G32)/2 -> #REF! | K32: =_xlfn.RANK.AVG(J32,#REF!,1) -> #REF! | M32: 3 | N32: =#REF! -> #REF! | O32: =(N32/100)*50 -> #REF! | Q32: =#REF! -> #REF! | R32: =($F32*0.5) -> #REF! | T32: =(N32+Q32) -> #REF! | U32: =(O32+R32)/2 -> #REF! | V32: =_xlfn.RANK.AVG(U32,#REF!,1) -> #REF!
B33: 12 | C33: =#REF! -> #REF! | D33: =(C33/100)*50 -> #REF! | F33: =#REF! -> #REF! | G33: =($F33*0.5) -> #REF! | I33: =(C33+F33) -> #REF! | J33: =(D33+G33)/2 -> #REF! | K33: =_xlfn.RANK.AVG(J33,#REF!,1) -> #REF! | M33: 12 | N33: =#REF! -> #REF! | O33: =(N33/100)*50 -> #REF! | Q33: =#REF! -> #REF! | R33: =($F33*0.5) -> #REF! | T33: =(N33+Q33) -> #REF! | U33: =(O33+R33)/2 -> #REF! | V33: =_xlfn.RANK.AVG(U33,#REF!,1) -> #REF!

Sheet Semi-Final Results
A2: =Dashboard!A2 -> Mister & Miss BISU TROPIKO 2024
A3: =Dashboard!A3 -> HIMAMAT 2024
A4: =Dashboard!A4 -> September 6, 2023 | BISU Balilihan Multi-Purpose Covered Court
A7: SEMI-FINAL RESULTS
D10: Best in Production Number
D11: Category
B13: =INDEX('Semi-Final'!$B$15:$B$20,MATCH(MIN('Semi-Final'!$K$15:$K$20),'Semi-Final'!$K$15:$K$20,0)) -> 4 | F13: =INDEX('Semi-Final'!$M$15:$M$20,MATCH(MIN('Semi-Final'!$V$15:$V$20),'Semi-Final'!$V$15:$V$20,0)) -> 5
C14: =_xlfn.CONCAT("CANDIDATE NO. ",B13) -> CANDIDATE NO. 4 | H14: =_xlfn.CONCAT("CANDIDATE NO. ",F13) -> CANDIDATE NO. 5
B15: Male Candidate | F15: Female Candidate
D20: Best in Tropical Attire
D21: Category
B23: =INDEX('Semi-Final'!$B$28:$B$33,MATCH(MIN('Semi-Final'!K28:K33),'Semi-Final'!K28:K33,0)) -> #REF! | F23: =INDEX('Semi-Final'!M28:M33,MATCH(MIN('Semi-Final'!V28:V33),'Semi-Final'!V28:V33,0)) -> #REF!
C24: =_xlfn.CONCAT("CANDIDATE NO. ",B23) -> #REF! | H24: =_xlfn.CONCAT("CANDIDATE NO. ",F23) -> #REF!
B25: Male Candidate | F25: Female Candidate
D29: Best in Casual Interview
D30: Category
B32: =INDEX('Semi-Final'!$B$41:$B$46,MATCH(MIN('Semi-Final'!$K$41:$K$46),'Semi-Final'!$K$41:$K$46,0)) -> 6 | F32: =INDEX('Semi-Final'!M41:M46,MATCH(MIN('Semi-Final'!V41:V46),'Semi-Final'!V41:V46,0)) -> 2
C33: =_xlfn.CONCAT("CANDIDATE NO. ",B32) -> CANDIDATE NO. 6 | H33: =_xlfn.CONCAT("CANDIDATE NO. ",F32) -> CANDIDATE NO. 2
B34: Male Candidate | F34: Female Candidate
D38: Top 3 Finalists
D39: Category
B41: =INDEX('Semi-Final'!$B$71:$B$76,MATCH(SMALL('Semi-Final'!$K$71:$K$76,1),'Semi-Final'!$K$71:$K$76,0)) -> #REF! | E41: =INDEX('Semi-Final'!$B$71:$B$76,MATCH(SMALL('Semi-Final'!$K$71:$K$76,2),'Semi-Final'!$K$71:$K$76,0)) -> #REF! | H41: =INDEX('Semi-Final'!$B$71:$B$76,MATCH(SMALL('Semi-Final'!$K$71:$K$76,3),'Semi-Final'!$K$71:$K$76,0)) -> #REF!
B42: =_xlfn.CONCAT("CANDIDATE NO. ",B41) -> #REF! | C42: =_xlfn.CONCAT("CANDIDATE NO. ",B41) -> #REF! | E42: =_xlfn.CONCAT("CANDIDATE NO. ",E41) -> #REF! | F42: =_xlfn.CONCAT("CANDIDATE NO. ",E41) -> #REF! | H42: =_xlfn.CONCAT("CANDIDATE NO. ",H41) -> #REF! | I42: =_xlfn.CONCAT("CANDIDATE NO. ",H41) -> #REF!
B43: Male Candidate | E43: Male Candidate | H43: Male Candidate
B45: =INDEX('Semi-Final'!$M$71:$M$76,MATCH(SMALL('Semi-Final'!$V$71:$V$76,1),'Semi-Final'!$V$71:$V$76,0)) -> #REF! | E45: =INDEX('Semi-Final'!$M$71:$M$76,MATCH(SMALL('Semi-Final'!$V$71:$V$76,2),'Semi-Final'!$V$71:$V$76,0)) -> #REF! | H45: =INDEX('Semi-Final'!$M$71:$M$76,MATCH(SMALL('Semi-Final'!$V$71:$V$76,3),'Semi-Final'!$V$71:$V$76,0)) -> #REF!
B46: =_xlfn.CONCAT("CANDIDATE NO. ",B45) -> #REF! | C46: =_xlfn.CONCAT("CANDIDATE NO. ",B45) -> #REF! | E46: =_xlfn.CONCAT("CANDIDATE NO. ",E45) -> #REF! | F46: =_xlfn.CONCAT("CANDIDATE NO. ",E45) -> #REF! | H46: =_xlfn.CONCAT("CANDIDATE NO. ",H45) -> #REF! | I46: =_xlfn.CONCAT("CANDIDATE NO. ",H45) -> #REF!
B47: Female Candidate | E47: Female Candidate | H47: Female Candidate
B52: RANDALL LYN B. BLASCO | E52: ENGR. EDUARDO B. CARPIO, JR. | H52: MA. KATHLEEN DUREEN M. TRAVERO
B53: Judge 2 | E53: Chairman of the Board of Judges | H53: Judge 3
E54: Judge 1
E57: JAMES ANTHONY B. ESTOCADO
E58: Tabulator

Sheet Final Results
A2: =Dashboard!A2 -> Mister & Miss BISU TROPIKO 2024
A3: =Dashboard!A3 -> HIMAMAT 2024
A4: =Dashboard!A4 -> September 6, 2023 | BISU Balilihan Multi-Purpose Covered Court
A7: FINAL RESULTS
C10: Mister & Miss BISU Tropiko 2024 - Second Runners-Up
D11: Category
B13: =INDEX(Final!B18:B20,MATCH(SMALL(Final!K18:K20,3),Final!K18:K20,0)) -> #REF! | F13: =INDEX(Final!M18:M20,MATCH(SMALL(Final!V18:V20,3),Final!V18:V20,0)) -> #REF!
C14: =_xlfn.CONCAT("CANDIDATE NO. ",B13) -> #REF! | H14: =_xlfn.CONCAT("CANDIDATE NO. ",F13) -> #REF!
B15: Male Candidate | F15: Female Candidate
C20: Mister & Miss BISU Tropiko 2024 - First Runners-Up
D21: Category
B23: =INDEX(Final!B18:B20,MATCH(SMALL(Final!K18:K20,2),Final!K18:K20,0)) -> #REF! | F23: =INDEX(Final!M18:M20,MATCH(SMALL(Final!V18:V20,2),Final!V18:V20,0)) -> #REF!
C24: =_xlfn.CONCAT("CANDIDATE NO. ",B23) -> #REF! | H24: =_xlfn.CONCAT("CANDIDATE NO. ",F23) -> #REF!
B25: Male Candidate | F25: Female Candidate
C29: Mister & Miss BISU Tropiko 2024
D30: Category
B32: =INDEX(Final!B18:B20,MATCH(SMALL(Final!K18:K20,1),Final!K18:K20,0)) -> #REF! | F32: =INDEX(Final!M18:M20,MATCH(SMALL(Final!V18:V20,1),Final!V18:V20,0)) -> #REF!
C33: =_xlfn.CONCAT("CANDIDATE NO. ",B32) -> #REF! | H33: =_xlfn.CONCAT("CANDIDATE NO. ",F32) -> #REF!
B34: Male Candidate | F34: Female Candidate
B40: RANDALL LYN B. BLASCO | E40: ENGR. EDUARDO B. CARPIO, JR. | F40: ANGELA A. CROWELL | H40: MA. KATHLEEN DUREEN M. TRAVERO | I40: MARIANITO JOSE M. LUSPO
B41: Judge 2 | E41: Chairman of the Board of Judges | H41: Judge 3
E42: Judge 1
E45: JAMES ANTHONY B. ESTOCADO
E46: Tabulator
